Workbook

Sheet Guide
B1: Professional DCF Valuation Model
B2: Built 2026-06-14 | Gold cells = inputs | White cells = formulas
B4: [Stock Search] One command to build and populate — pick your stock and date:
B5: python build_dcf.py AAPL (live data)
B6: python build_dcf.py AAPL --date 2020-03-23 (COVID crash low)
B7: python build_dcf.py AAPL --date 2008 (financial crisis)
B8: Microsoft 365: select B5 then Data > Stocks to link live data.
B9: [Assumptions] Edit all gold cells. Revenue growth, margins, WACC inputs, terminal value.
B10: To refresh data only: python update_dcf.py AAPL (keeps your thesis intact)
B11: [Income Statement] Historical (grey) + 10-year projection. FCF computed automatically.
B12: [WACC] Cost of equity (CAPM), cost of debt, capital structure -> WACC.
B13: [DCF Valuation] Discounted FCFs + terminal value -> Enterprise Value -> Implied Price.
B14: [Sensitivity] Implied price vs WACC x terminal growth rate. Green = upside.

Sheet Stock Search
B1: STOCK SEARCH - Data Input Center
B2: Enter ticker in B5 below. Microsoft 365: select B5, then Data > Stocks to link live data. Or run update_dcf.py to auto-populate.
B4: TICKER | C4: PRICE ($) | D4: COMPANY | E4: LAST UPDATED
B5: MSFT | C5: 390.34 | D5: Microsoft Corporation | E5: 2026-06-14
B7: PRICE & RANGE
B8: Current Price / 52-Week High / 52-Week Low | C8: 390.34 | D8: 551.05 | E8: 355.51
B9: SHARES & MARKET CAP
B10: Market Cap ($M) / Shares Out. (M) / Float % | C10: 2902586.6 | D10: 7428.4 | E10: 0.9985
B11: INCOME (TTM, $M)
B12: Revenue / EBITDA / Net Income | C12: 318273 | D12: 184457 | E12: 125216
B13: BALANCE SHEET ($M)
B14: Total Debt / Cash / Net Debt | C14: 125432 | D14: 78228 | E14: =C16-D16
B15: VALUATION
B16: P/E (TTM) / EV/EBITDA / Beta | C16: 23.3 | D16: 16 | E16: 1.07
B18: MICROSOFT 365 STOCKS DATA TYPE - INSTRUCTIONS
B19: 1. Type ticker in B5 (e.g. AAPL, MSFT, GOOGL, NVDA)
B20: 2. With B5 selected: click Data tab > Stocks button in ribbon
B21: 3. Excel converts the text to a linked Stocks data type (shows stock icon)
B22: 4. Click the icon to browse available fields, or type =B5.Price to extract any field
B23: 5. STOCKHISTORY(B5, start_date, end_date) returns historical price table
B25: PYTHON AUTO-FILL (works with any Excel version):
B26: pip install yfinance openpyxl
B27: python update_dcf.py AAPL

Sheet Assumptions
B1: MODEL ASSUMPTIONS - Edit Gold Cells Only
B2: All dollar amounts in USD millions. Percentages as decimals (10% = 0.10).
B4: COMPANY
B5: Company Name | C5: Microsoft Corporation | D5: Ticker | E5: MSFT
B6: Fiscal Year End | C6: September | D6: Currency | E6: USD
B7: Current Price ($) | C7: 390.34 | D7: Shares Out. (M) | E7: 7428.4
B8: Total Debt ($M) | C8: 125432 | D8: Cash ($M) | E8: 78228
B9: REVENUE GROWTH (10-year projection ramp)
B10: Y1 Revenue Growth | C10: 0.2182 | D10: Y2 Revenue Growth | E10: 0.19
B11: Y3 Revenue Growth | C11: 0.1633 | D11: Y4 Revenue Growth | E11: 0.1382
B12: Y5 Revenue Growth | C12: 0.1148 | D12: Y6 Revenue Growth | E12: 0.0933
B13: Y7 Revenue Growth | C13: 0.0739 | D13: Y8 Revenue Growth | E13: 0.0568
B14: Y9 Revenue Growth | C14: 0.0423 | D14: Y10 Revenue Growth | E14: 0.0311
B15: MARGIN ASSUMPTIONS · NWC source: Damodaran wcdata.html — pages.stern.nyu.edu/~adamodar/New_Home_Page/datafile/wcdata.html (sector-specific benchmark auto-applied by update_dcf.py)
B16: Gross Margin % | C16: 0.6092 | D16: EBITDA Margin % | E16: 0.5796
B17: D&A (% of Revenue) | C17: 0.1073 | D17: CapEx (% of Revenue) | E17: 0.2028
B18: Net Working Cap (% Rev) | C18: -0.0224 | D18: Tax Rate | E18: 0.155
B19: SBC (% of Revenue) | C19: 0.025
B20: WACC INPUTS · Source: Damodaran Implied ERP — pages.stern.nyu.edu/~adamodar/New_Home_Page/datafile/histimpl.html (2025: Rf=4.18%, ERP=4.23%)
B21: Risk-Free Rate (Rf) | C21: 0.0418 | D21: Equity Risk Premium | E21: 0.0423
B22: Beta (Levered) | C22: 1.07 | D22: Pre-Tax Cost of Debt | E22: 0.038
B23: Debt / Capital (Wd) [market-value, auto-computed] | C23: =1-E23 | D23: Equity / Capital (We) [Price × Shares / (Mkt Cap + Debt)] | E23: =(C7*E7)/((C7*E7)+C8)
B24: WACC (from WACC sheet) | C24: =WACC!E17
B25: TERMINAL VALUE
B26: Terminal Growth Rate | C26: 0.025 | D26: Exit EBITDA Multiple | E26: 18
B27: HISTORICAL REVENUE (for Y0 base)
B28: Base Revenue ($M) [LTM/Y0] | C28: 318273 | D28: FY-1 Revenue ($M) | E28: 245122
B29: FY-2 Revenue ($M) | C29: 211915
B30: ADVANCED SETTINGS (change here — all sheets update automatically)
B31: Mid-Year Offset (0 = yr-end, 0.5 = mid-yr) | C31: 0 | D31: SBC Add-Back Scale (1 = full, 0 = exclude) | E31: 0
B32: Mid-Year: 0 = cash flows arrive year-end (default) | 0.5 = mid-year convention (raises implied price ~4–6%) | 0.3 or 0.7 also valid. SBC: 1 = full add-back | 0.5 = partial | 0 = exclude (most conservative).
B34: INVESTMENT THESIS (free text)
B35: Company and thesis notes here.
B36: Key risks:
B37: Key catalysts:

Sheet Income Statement
B1: INCOME STATEMENT & FREE CASH FLOW (USD $M)
C3: HISTORICAL | F3: PROJECTED (10 years)
B4: Metric (USD $M) | C4: FY2024A | D4: FY2025A | E4: FY2026A | F4: FY2027E | G4: FY2028E | H4: FY2029E | I4: FY2030E | J4: FY2031E | K4: FY2032E | L4: FY2033E | M4: FY2034E | N4: FY2035E | O4: FY2036E
B5: REVENUE
B6: Revenue Growth % | C6: — | D6: =(D7-C7)/C7 | E6: =(E7-D7)/D7 | F6: =Assumptions!C10 | G6: =Assumptions!E10 | H6: =Assumptions!C11 | I6: =Assumptions!E11 | J6: =Assumptions!C12 | K6: =Assumptions!E12 | L6: =Assumptions!C13 | M6: =Assumptions!E13 | N6: =Assumptions!C14 | O6: =Assumptions!E14
B7: Revenue | C7: =Assumptions!C29 | D7: =Assumptions!E28 | E7: =Assumptions!C28 | F7: =E7*(1+Assumptions!C10) | G7: =F7*(1+Assumptions!E10) | H7: =G7*(1+Assumptions!C11) | I7: =H7*(1+Assumptions!E11) | J7: =I7*(1+Assumptions!C12) | K7: =J7*(1+Assumptions!E12) | L7: =K7*(1+Assumptions!C13) | M7: =L7*(1+Assumptions!E13) | N7: =M7*(1+Assumptions!C14) | O7: =N7*(1+Assumptions!E14)
B8: GROSS PROFIT
B9: Gross Margin % | C9: 0.432 | D9: 0.433 | E9: 0.435 | F9: =Assumptions!C16 | G9: =Assumptions!C16 | H9: =Assumptions!C16 | I9: =Assumptions!C16 | J9: =Assumptions!C16 | K9: =Assumptions!C16 | L9: =Assumptions!C16 | M9: =Assumptions!C16 | N9: =Assumptions!C16 | O9: =Assumptions!C16
B10: Gross Profit | C10: =C7*C9 | D10: =D7*D9 | E10: =E7*E9 | F10: =F7*F9 | G10: =G7*G9 | H10: =H7*H9 | I10: =I7*I9 | J10: =J7*J9 | ... O10: =O7*O9
B11: OPERATING EXPENSES -> EBITDA
B12: EBITDA Margin % | C12: 0.327 | D12: 0.33 | E12: 0.335 | F12: =Assumptions!E16 | G12: =Assumptions!E16 | H12: =Assumptions!E16 | I12: =Assumptions!E16 | J12: =Assumptions!E16 | K12: =Assumptions!E16 | L12: =Assumptions!E16 | M12: =Assumptions!E16 | N12: =Assumptions!E16 | O12: =Assumptions!E16
B13: EBITDA | C13: =C7*C12 | D13: =D7*D12 | E13: =E7*E12 | F13: =F7*F12 | G13: =G7*G12 | H13: =H7*H12 | I13: =I7*I12 | J13: =J7*J12 | ... O13: =O7*O12
B14: OpEx (= Gross Profit - EBITDA) | C14: =C10-C13 | D14: =D10-D13 | E14: =E10-E13 | F14: =F10-F13 | G14: =G10-G13 | H14: =H10-H13 | I14: =I10-I13 | J14: =J10-J13 | ... O14: =O10-O13
B15: D&A -> EBIT
B16: D&A % of Revenue | C16: 0.025 | D16: 0.025 | E16: 0.025 | F16: =Assumptions!C17 | G16: =Assumptions!C17 | H16: =Assumptions!C17 | I16: =Assumptions!C17 | J16: =Assumptions!C17 | K16: =Assumptions!C17 | L16: =Assumptions!C17 | M16: =Assumptions!C17 | N16: =Assumptions!C17 | O16: =Assumptions!C17
B17: D&A ($M) | C17: =C16*C7 | D17: =D16*D7 | E17: =E16*E7 | F17: =F16*F7 | G17: =G16*G7 | H17: =H16*H7 | I17: =I16*I7 | J17: =J16*J7 | ... O17: =O16*O7
B18: EBIT (Operating Income) | C18: =C13-C17 | D18: =D13-D17 | E18: =E13-E17 | F18: =F13-F17 | G18: =G13-G17 | H18: =H13-H17 | I18: =I13-I17 | J18: =J13-J17 | ... O18: =O13-O17
B19: EBIT Margin % | C19: =IF(C7=0,0,C18/C7) | D19: =IF(D7=0,0,D18/D7) | E19: =IF(E7=0,0,E18/E7) | F19: =IF(F7=0,0,F18/F7) | G19: =IF(G7=0,0,G18/G7) | H19: =IF(H7=0,0,H18/H7) | I19: =IF(I7=0,0,I18/I7) | J19: =IF(J7=0,0,J18/J7) | ... O19: =IF(O7=0,0,O18/O7)
B20: NOPAT (Net Operating Profit After Tax)
B21: Tax Rate % | C21: 0.14 | D21: 0.148 | E21: 0.155 | F21: =Assumptions!E18 | G21: =Assumptions!E18 | H21: =Assumptions!E18 | I21: =Assumptions!E18 | J21: =Assumptions!E18 | K21: =Assumptions!E18 | L21: =Assumptions!E18 | M21: =Assumptions!E18 | N21: =Assumptions!E18 | O21: =Assumptions!E18
B22: NOPAT = EBIT x (1 - Tax Rate) | C22: =C18*(1-C21) | D22: =D18*(1-D21) | E22: =E18*(1-E21) | F22: =F18*(1-F21) | G22: =G18*(1-G21) | H22: =H18*(1-H21) | I22: =I18*(1-I21) | J22: =J18*(1-J21) | ... O22: =O18*(1-O21)
B23: FREE CASH FLOW TO FIRM (FCFF)
B24: (+) D&A add-back ($M) | C24: =C17 | D24: =D17 | E24: =E17 | F24: =F17 | G24: =G17 | H24: =H17 | I24: =I17 | J24: =J17 | ... O24: =O17
B25: (-) CapEx % of Revenue | C25: 0.028 | D25: 0.028 | E25: 0.028 | F25: =Assumptions!E17 | G25: =Assumptions!E17 | H25: =Assumptions!E17 | I25: =Assumptions!E17 | J25: =Assumptions!E17 | K25: =Assumptions!E17 | L25: =Assumptions!E17 | M25: =Assumptions!E17 | N25: =Assumptions!E17 | O25: =Assumptions!E17
B26: (-) CapEx ($M) | C26: =C25*C7 | D26: =D25*D7 | E26: =E25*E7 | F26: =F25*F7 | G26: =G25*G7 | H26: =H25*H7 | I26: =I25*I7 | J26: =J25*J7 | ... O26: =O25*O7
B27: (+/-) Change in Net Working Capital ($M) | C27: -3200 | D27: -3800 | E27: =-Assumptions!C18*(E7-D7) | F27: =-(Assumptions!C18*F7-Assumptions!C18*E7) | G27: =-(Assumptions!C18*G7-Assumptions!C18*F7) | H27: =-(Assumptions!C18*H7-Assumptions!C18*G7) | I27: =-(Assumptions!C18*I7-Assumptions!C18*H7) | J27: =-(Assumptions!C18*J7-Assumptions!C18*I7) | K27: =-(Assumptions!C18*K7-Assumptions!C18*J7) | L27: =-(Assumptions!C18*L7-Assumptions!C18*K7) | M27: =-(Assumptions!C18*M7-Assumptions!C18*L7) | N27: =-(Assumptions!C18*N7-Assumptions!C18*M7) | O27: =-(Assumptions!C18*O7-Assumptions!C18*N7)
B28: (+) Stock-Based Comp ($M) | C28: 9200 | D28: 9700 | E28: =Assumptions!C19*E7 | F28: =Assumptions!C19*F7 | G28: =Assumptions!C19*G7 | H28: =Assumptions!C19*H7 | I28: =Assumptions!C19*I7 | J28: =Assumptions!C19*J7 | K28: =Assumptions!C19*K7 | L28: =Assumptions!C19*L7 | M28: =Assumptions!C19*M7 | N28: =Assumptions!C19*N7 | O28: =Assumptions!C19*O7
B29: FCFF (Free Cash Flow to Firm) | C29: =MAX(0,C22+C24-C26+C27+C28*Assumptions!E31) | D29: =MAX(0,D22+D24-D26+D27+D28*Assumptions!E31) | E29: =MAX(0,E22+E24-E26+E27+E28*Assumptions!E31) | F29: =MAX(0,F22+F24-F26+F27+F28*Assumptions!E31) | G29: =MAX(0,G22+G24-G26+G27+G28*Assumptions!E31) | H29: =MAX(0,H22+H24-H26+H27+H28*Assumptions!E31) | I29: =MAX(0,I22+I24-I26+I27+I28*Assumptions!E31) | J29: =MAX(0,J22+J24-J26+J27+J28*Assumptions!E31) | K29: =MAX(0,K22+K24-K26+K27+K28*Assumptions!E31) | L29: =MAX(0,L22+L24-L26+L27+L28*Assumptions!E31) | M29: =MAX(0,M22+M24-M26+M27+M28*Assumptions!E31) | N29: =MAX(0,N22+N24-N26+N27+N28*Assumptions!E31) | O29: =MAX(0,O22+O24-O26+O27+O28*Assumptions!E31)
B30: FCF Margin % | C30: =IF(C7=0,0,C29/C7) | D30: =IF(D7=0,0,D29/D7) | E30: =IF(E7=0,0,E29/E7) | F30: =IF(F7=0,0,F29/F7) | G30: =IF(G7=0,0,G29/G7) | H30: =IF(H7=0,0,H29/H7) | I30: =IF(I7=0,0,I29/I7) | J30: =IF(J7=0,0,J29/J7) | ... O30: =IF(O7=0,0,O29/O7)
B32: 10-YEAR FCF PROJECTION (from model above)

Sheet WACC
B1: WACC - Weighted Average Cost of Capital
B2: WACC = Ke x We + Kd x (1-t) x Wd | Sources: Assumptions sheet
B4: COST OF EQUITY - CAPM: Ke = Rf + Beta x ERP (Hamada re-levering)
B5: Risk-Free Rate (Rf) | C5: =Assumptions!C21 | D5: Equity Risk Premium | E5: =Assumptions!E21
B6: Beta (Levered, from market data) | C6: =Assumptions!C22
B7: Unlevered Beta [Hamada: Beta_L / (1+(1-t)×Wd/We)] | C7: =Assumptions!C22/(1+(1-Assumptions!E18)*Assumptions!C23/Assumptions!E23) | D7: Re-levered Beta [Beta_U × (1+(1-t)×Wd/We)] | E7: =C7*(1+(1-Assumptions!E18)*Assumptions!C23/Assumptions!E23)
B8: COST OF EQUITY (Ke) | E8: =Assumptions!C21+E7*Assumptions!E21
B9: COST OF DEBT - After Tax: Kd_at = Kd x (1 - Tax Rate)
B10: Pre-Tax Cost of Debt (Kd) | C10: =Assumptions!E22 | D10: Tax Rate | E10: =Assumptions!E18
B11: AFTER-TAX COST OF DEBT (Kd) | E11: =C10*(1-E10)
B12: CAPITAL STRUCTURE WEIGHTS
B13: Equity / Capital (We) | C13: =Assumptions!E23 | D13: Debt / Capital (Wd) | E13: =Assumptions!C23
B14: Check: We + Wd should = 1.0 | C14: =C13+E13 | D14: Status: | E14: =IF(ABS(C13+E13-1)<0.001,"OK - sums to 100%","CHECK WEIGHTS")
B15: WACC CALCULATION
B16: Ke x We (equity component) | C16: =WACC!E8*C13 | D16: Kd(1-t) x Wd (debt component) | E16: =WACC!E11*E13
B17: WACC = Ke x We + Kd(1-t) x Wd | E17: =C16+E16
B19: Note: WACC above flows into DCF Valuation sheet automatically. Sensitivity analysis spans +/-150bps in the Sensitivity sheet.

Sheet DCF Valuation
B1: DCF VALUATION - Enterprise & Equity Value Bridge
B3: DISCOUNT RATE & KEY INPUTS
B4: WACC | C4: =WACC!E17 | D4: Ke×We + Kd(1-t)×Wd — from WACC sheet
B5: Terminal Growth Rate (g) | C5: =Assumptions!C26 | D5: Long-run FCF growth after Year 10 — Assumptions
B6: Exit EBITDA Multiple | C6: =Assumptions!E26 | D6: Reference only; Gordon Growth is primary TV method
B7: Net Debt ($M) | C7: =Assumptions!C8-Assumptions!E8 | D7: Total Debt minus Cash — from Assumptions
B8: Shares Outstanding (M) | C8: =Assumptions!E7 | D8: Diluted share count — from Assumptions
B9: PROJECTED FCF BY YEAR (from Income Statement)
B10: Year | C10: FY2027 | D10: FY2028 | E10: FY2029 | F10: FY2030 | G10: FY2031 | H10: FY2032 | I10: FY2033 | J10: FY2034 | K10: FY2035 | L10: FY2036
B11: FCFF ($M) | C11: ='Income Statement'!F29 | D11: ='Income Statement'!G29 | E11: ='Income Statement'!H29 | F11: ='Income Statement'!I29 | G11: ='Income Statement'!J29 | H11: ='Income Statement'!K29 | I11: ='Income Statement'!L29 | J11: ='Income Statement'!M29 | ... L11: ='Income Statement'!O29
B12: Discount Period (t) | C12: 1 | D12: 2 | E12: 3 | F12: 4 | G12: 5 | H12: 6 | I12: 7 | J12: 8 | K12: 9 | L12: 10
B13: Discount Factor [1/(1+WACC)^(t − mid-yr offset)] | C13: =1/(1+C4)^(C12-Assumptions!C31) | D13: =1/(1+C4)^(D12-Assumptions!C31) | E13: =1/(1+C4)^(E12-Assumptions!C31) | F13: =1/(1+C4)^(F12-Assumptions!C31) | G13: =1/(1+C4)^(G12-Assumptions!C31) | H13: =1/(1+C4)^(H12-Assumptions!C31) | I13: =1/(1+C4)^(I12-Assumptions!C31) | J13: =1/(1+C4)^(J12-Assumptions!C31) | K13: =1/(1+C4)^(K12-Assumptions!C31) | L13: =1/(1+C4)^(L12-Assumptions!C31)
B14: PV of FCFF ($M) | C14: =C11*C13 | D14: =D11*D13 | E14: =E11*E13 | F14: =F11*F13 | G14: =G11*G13 | H14: =H11*H13 | I14: =I11*I13 | J14: =J11*J13 | ... L14: =L11*L13
B15: Sum of PV(FCFF), Years 1-10 | C15: =SUM(C14:L14)
B16: TERMINAL VALUE
B17: Gordon Growth TV = FCFF_Y10 * (1+g) / (WACC - g) | C17: =L11*(1+C5)/MAX(C4-C5,0.01) | D17: PV of TV (Gordon Growth) | E17: =C17/(1+C4)^(10-Assumptions!C31)
B18: Exit Multiple TV = EBITDA_Y11 x Multiple [forward; reference only] | C18: ='Income Statement'!O13*(1+C5)*C6 | D18: PV of TV (Exit Multiple) | E18: =C18/(1+C4)^(10-Assumptions!C31)
B19: VALUATION BRIDGE
B20: (+) Sum of PV(FCF) - Years 1-10 | C20: =C15
B21: (+) PV of Terminal Value (Gordon Growth - PRIMARY) | C21: =E17
B22: ENTERPRISE VALUE | C22: =C20+C21
B23: (-) Net Debt ($M) | C23: =C7
B24: EQUITY VALUE | C24: =MAX(0,C22-C23)
B25: Shares Outstanding (M) | C25: =C8
B26: IMPLIED SHARE PRICE (DCF) | C26: =C24/C25
B27: Current Stock Price ($) | C27: =Assumptions!C7
B28: Upside / (Downside) % | C28: =(C26-C27)/C27
B29: VALUATION COMPOSITION
B30: PV of FCFs as % of Enterprise Value | C30: =IF(C22=0,0,C20/C22)
B31: PV of Terminal Value as % of Enterprise Value | C31: =IF(C22=0,0,C21/C22)
B32: Implied EV / EBITDA Multiple (LTM) | C32: =IF('Income Statement'!E13=0,0,C22/'Income Statement'!E13)

Sheet Sensitivity
B1: SENSITIVITY ANALYSIS - Implied Share Price vs Key Drivers
B2: Green = above current stock price (upside) | Red = below (downside) | Base case uses WACC and TGR from WACC and Assumptions sheets.
B4: TABLE 1 - Implied Share Price vs WACC x Terminal Growth Rate
B5: WACC \ TGR | C5: ='DCF Valuation'!C5+(-0.01) | D5: ='DCF Valuation'!C5+(-0.005) | E5: ='DCF Valuation'!C5+(0.0) | F5: ='DCF Valuation'!C5+(0.005) | G5: ='DCF Valuation'!C5+(0.01) | H5: ='DCF Valuation'!C5+(0.015)
B6: ='DCF Valuation'!C4+(-0.015) | C6: =IFERROR(MAX(0,SUMPRODUCT('Income Statement'!F29:O29,1/(1+B6)^({1,2,3,4,5,6,7,8,9,10}-Assumptions!C31))+'Income Statement'!O29*(1+C5)/MAX(B6-C5,0.01)/(1+B6)^(10-Assumptions!C31)-(Assumptions!C8-Assumptions!E8))/Assumptions!E7,"—") | D6: =IFERROR(MAX(0,SUMPRODUCT('Income Statement'!F29:O29,1/(1+B6)^({1,2,3,4,5,6,7,8,9,10}-Assumptions!C31))+'Income Statement'!O29*(1+D5)/MAX(B6-D5,0.01)/(1+B6)^(10-Assumptions!C31)-(Assumptions!C8-Assumptions!E8))/Assumptions!E7,"—") | E6: =IFERROR(MAX(0,SUMPRODUCT('Income Statement'!F29:O29,1/(1+B6)^({1,2,3,4,5,6,7,8,9,10}-Assumptions!C31))+'Income Statement'!O29*(1+E5)/MAX(B6-E5,0.01)/(1+B6)^(10-Assumptions!C31)-(Assumptions!C8-Assumptions!E8))/Assumptions!E7,"—") | F6: =IFERROR(MAX(0,SUMPRODUCT('Income Statement'!F29:O29,1/(1+B6)^({1,2,3,4,5,6,7,8,9,10}-Assumptions!C31))+'Income Statement'!O29*(1+F5)/MAX(B6-F5,0.01)/(1+B6)^(10-Assumptions!C31)-(Assumptions!C8-Assumptions!E8))/Assumptions!E7,"—") | G6: =IFERROR(MAX(0,SUMPRODUCT('Income Statement'!F29:O29,1/(1+B6)^({1,2,3,4,5,6,7,8,9,10}-Assumptions!C31))+'Income Statement'!O29*(1+G5)/MAX(B6-G5,0.01)/(1+B6)^(10-Assumptions!C31)-(Assumptions!C8-Assumptions!E8))/Assumptions!E7,"—") | H6: =IFERROR(MAX(0,SUMPRODUCT('Income Statement'!F29:O29,1/(1+B6)^({1,2,3,4,5,6,7,8,9,10}-Assumptions!C31))+'Income Statement'!O29*(1+H5)/MAX(B6-H5,0.01)/(1+B6)^(10-Assumptions!C31)-(Assumptions!C8-Assumptions!E8))/Assumptions!E7,"—")
B7: ='DCF Valuation'!C4+(-0.01) | C7: =IFERROR(MAX(0,SUMPRODUCT('Income Statement'!F29:O29,1/(1+B7)^({1,2,3,4,5,6,7,8,9,10}-Assumptions!C31))+'Income Statement'!O29*(1+C5)/MAX(B7-C5,0.01)/(1+B7)^(10-Assumptions!C31)-(Assumptions!C8-Assumptions!E8))/Assumptions!E7,"—") | D7: =IFERROR(MAX(0,SUMPRODUCT('Income Statement'!F29:O29,1/(1+B7)^({1,2,3,4,5,6,7,8,9,10}-Assumptions!C31))+'Income Statement'!O29*(1+D5)/MAX(B7-D5,0.01)/(1+B7)^(10-Assumptions!C31)-(Assumptions!C8-Assumptions!E8))/Assumptions!E7,"—") | E7: =IFERROR(MAX(0,SUMPRODUCT('Income Statement'!F29:O29,1/(1+B7)^({1,2,3,4,5,6,7,8,9,10}-Assumptions!C31))+'Income Statement'!O29*(1+E5)/MAX(B7-E5,0.01)/(1+B7)^(10-Assumptions!C31)-(Assumptions!C8-Assumptions!E8))/Assumptions!E7,"—") | F7: =IFERROR(MAX(0,SUMPRODUCT('Income Statement'!F29:O29,1/(1+B7)^({1,2,3,4,5,6,7,8,9,10}-Assumptions!C31))+'Income Statement'!O29*(1+F5)/MAX(B7-F5,0.01)/(1+B7)^(10-Assumptions!C31)-(Assumptions!C8-Assumptions!E8))/Assumptions!E7,"—") | G7: =IFERROR(MAX(0,SUMPRODUCT('Income Statement'!F29:O29,1/(1+B7)^({1,2,3,4,5,6,7,8,9,10}-Assumptions!C31))+'Income Statement'!O29*(1+G5)/MAX(B7-G5,0.01)/(1+B7)^(10-Assumptions!C31)-(Assumptions!C8-Assumptions!E8))/Assumptions!E7,"—") | H7: =IFERROR(MAX(0,SUMPRODUCT('Income Statement'!F29:O29,1/(1+B7)^({1,2,3,4,5,6,7,8,9,10}-Assumptions!C31))+'Income Statement'!O29*(1+H5)/MAX(B7-H5,0.01)/(1+B7)^(10-Assumptions!C31)-(Assumptions!C8-Assumptions!E8))/Assumptions!E7,"—")
B8: ='DCF Valuation'!C4+(-0.005) | C8: =IFERROR(MAX(0,SUMPRODUCT('Income Statement'!F29:O29,1/(1+B8)^({1,2,3,4,5,6,7,8,9,10}-Assumptions!C31))+'Income Statement'!O29*(1+C5)/MAX(B8-C5,0.01)/(1+B8)^(10-Assumptions!C31)-(Assumptions!C8-Assumptions!E8))/Assumptions!E7,"—") | D8: =IFERROR(MAX(0,SUMPRODUCT('Income Statement'!F29:O29,1/(1+B8)^({1,2,3,4,5,6,7,8,9,10}-Assumptions!C31))+'Income Statement'!O29*(1+D5)/MAX(B8-D5,0.01)/(1+B8)^(10-Assumptions!C31)-(Assumptions!C8-Assumptions!E8))/Assumptions!E7,"—") | E8: =IFERROR(MAX(0,SUMPRODUCT('Income Statement'!F29:O29,1/(1+B8)^({1,2,3,4,5,6,7,8,9,10}-Assumptions!C31))+'Income Statement'!O29*(1+E5)/MAX(B8-E5,0.01)/(1+B8)^(10-Assumptions!C31)-(Assumptions!C8-Assumptions!E8))/Assumptions!E7,"—") | F8: =IFERROR(MAX(0,SUMPRODUCT('Income Statement'!F29:O29,1/(1+B8)^({1,2,3,4,5,6,7,8,9,10}-Assumptions!C31))+'Income Statement'!O29*(1+F5)/MAX(B8-F5,0.01)/(1+B8)^(10-Assumptions!C31)-(Assumptions!C8-Assumptions!E8))/Assumptions!E7,"—") | G8: =IFERROR(MAX(0,SUMPRODUCT('Income Statement'!F29:O29,1/(1+B8)^({1,2,3,4,5,6,7,8,9,10}-Assumptions!C31))+'Income Statement'!O29*(1+G5)/MAX(B8-G5,0.01)/(1+B8)^(10-Assumptions!C31)-(Assumptions!C8-Assumptions!E8))/Assumptions!E7,"—") | H8: =IFERROR(MAX(0,SUMPRODUCT('Income Statement'!F29:O29,1/(1+B8)^({1,2,3,4,5,6,7,8,9,10}-Assumptions!C31))+'Income Statement'!O29*(1+H5)/MAX(B8-H5,0.01)/(1+B8)^(10-Assumptions!C31)-(Assumptions!C8-Assumptions!E8))/Assumptions!E7,"—")
B9: ='DCF Valuation'!C4+(0.0) | C9: =IFERROR(MAX(0,SUMPRODUCT('Income Statement'!F29:O29,1/(1+B9)^({1,2,3,4,5,6,7,8,9,10}-Assumptions!C31))+'Income Statement'!O29*(1+C5)/MAX(B9-C5,0.01)/(1+B9)^(10-Assumptions!C31)-(Assumptions!C8-Assumptions!E8))/Assumptions!E7,"—") | D9: =IFERROR(MAX(0,SUMPRODUCT('Income Statement'!F29:O29,1/(1+B9)^({1,2,3,4,5,6,7,8,9,10}-Assumptions!C31))+'Income Statement'!O29*(1+D5)/MAX(B9-D5,0.01)/(1+B9)^(10-Assumptions!C31)-(Assumptions!C8-Assumptions!E8))/Assumptions!E7,"—") | E9: =IFERROR(MAX(0,SUMPRODUCT('Income Statement'!F29:O29,1/(1+B9)^({1,2,3,4,5,6,7,8,9,10}-Assumptions!C31))+'Income Statement'!O29*(1+E5)/MAX(B9-E5,0.01)/(1+B9)^(10-Assumptions!C31)-(Assumptions!C8-Assumptions!E8))/Assumptions!E7,"—") | F9: =IFERROR(MAX(0,SUMPRODUCT('Income Statement'!F29:O29,1/(1+B9)^({1,2,3,4,5,6,7,8,9,10}-Assumptions!C31))+'Income Statement'!O29*(1+F5)/MAX(B9-F5,0.01)/(1+B9)^(10-Assumptions!C31)-(Assumptions!C8-Assumptions!E8))/Assumptions!E7,"—") | G9: =IFERROR(MAX(0,SUMPRODUCT('Income Statement'!F29:O29,1/(1+B9)^({1,2,3,4,5,6,7,8,9,10}-Assumptions!C31))+'Income Statement'!O29*(1+G5)/MAX(B9-G5,0.01)/(1+B9)^(10-Assumptions!C31)-(Assumptions!C8-Assumptions!E8))/Assumptions!E7,"—") | H9: =IFERROR(MAX(0,SUMPRODUCT('Income Statement'!F29:O29,1/(1+B9)^({1,2,3,4,5,6,7,8,9,10}-Assumptions!C31))+'Income Statement'!O29*(1+H5)/MAX(B9-H5,0.01)/(1+B9)^(10-Assumptions!C31)-(Assumptions!C8-Assumptions!E8))/Assumptions!E7,"—")
B10: ='DCF Valuation'!C4+(0.005) | C10: =IFERROR(MAX(0,SUMPRODUCT('Income Statement'!F29:O29,1/(1+B10)^({1,2,3,4,5,6,7,8,9,10}-Assumptions!C31))+'Income Statement'!O29*(1+C5)/MAX(B10-C5,0.01)/(1+B10)^(10-Assumptions!C31)-(Assumptions!C8-Assumptions!E8))/Assumptions!E7,"—") | D10: =IFERROR(MAX(0,SUMPRODUCT('Income Statement'!F29:O29,1/(1+B10)^({1,2,3,4,5,6,7,8,9,10}-Assumptions!C31))+'Income Statement'!O29*(1+D5)/MAX(B10-D5,0.01)/(1+B10)^(10-Assumptions!C31)-(Assumptions!C8-Assumptions!E8))/Assumptions!E7,"—") | E10: =IFERROR(MAX(0,SUMPRODUCT('Income Statement'!F29:O29,1/(1+B10)^({1,2,3,4,5,6,7,8,9,10}-Assumptions!C31))+'Income Statement'!O29*(1+E5)/MAX(B10-E5,0.01)/(1+B10)^(10-Assumptions!C31)-(Assumptions!C8-Assumptions!E8))/Assumptions!E7,"—") | F10: =IFERROR(MAX(0,SUMPRODUCT('Income Statement'!F29:O29,1/(1+B10)^({1,2,3,4,5,6,7,8,9,10}-Assumptions!C31))+'Income Statement'!O29*(1+F5)/MAX(B10-F5,0.01)/(1+B10)^(10-Assumptions!C31)-(Assumptions!C8-Assumptions!E8))/Assumptions!E7,"—") | G10: =IFERROR(MAX(0,SUMPRODUCT('Income Statement'!F29:O29,1/(1+B10)^({1,2,3,4,5,6,7,8,9,10}-Assumptions!C31))+'Income Statement'!O29*(1+G5)/MAX(B10-G5,0.01)/(1+B10)^(10-Assumptions!C31)-(Assumptions!C8-Assumptions!E8))/Assumptions!E7,"—") | H10: =IFERROR(MAX(0,SUMPRODUCT('Income Statement'!F29:O29,1/(1+B10)^({1,2,3,4,5,6,7,8,9,10}-Assumptions!C31))+'Income Statement'!O29*(1+H5)/MAX(B10-H5,0.01)/(1+B10)^(10-Assumptions!C31)-(Assumptions!C8-Assumptions!E8))/Assumptions!E7,"—")
B11: ='DCF Valuation'!C4+(0.01) | C11: =IFERROR(MAX(0,SUMPRODUCT('Income Statement'!F29:O29,1/(1+B11)^({1,2,3,4,5,6,7,8,9,10}-Assumptions!C31))+'Income Statement'!O29*(1+C5)/MAX(B11-C5,0.01)/(1+B11)^(10-Assumptions!C31)-(Assumptions!C8-Assumptions!E8))/Assumptions!E7,"—") | D11: =IFERROR(MAX(0,SUMPRODUCT('Income Statement'!F29:O29,1/(1+B11)^({1,2,3,4,5,6,7,8,9,10}-Assumptions!C31))+'Income Statement'!O29*(1+D5)/MAX(B11-D5,0.01)/(1+B11)^(10-Assumptions!C31)-(Assumptions!C8-Assumptions!E8))/Assumptions!E7,"—") | E11: =IFERROR(MAX(0,SUMPRODUCT('Income Statement'!F29:O29,1/(1+B11)^({1,2,3,4,5,6,7,8,9,10}-Assumptions!C31))+'Income Statement'!O29*(1+E5)/MAX(B11-E5,0.01)/(1+B11)^(10-Assumptions!C31)-(Assumptions!C8-Assumptions!E8))/Assumptions!E7,"—") | F11: =IFERROR(MAX(0,SUMPRODUCT('Income Statement'!F29:O29,1/(1+B11)^({1,2,3,4,5,6,7,8,9,10}-Assumptions!C31))+'Income Statement'!O29*(1+F5)/MAX(B11-F5,0.01)/(1+B11)^(10-Assumptions!C31)-(Assumptions!C8-Assumptions!E8))/Assumptions!E7,"—") | G11: =IFERROR(MAX(0,SUMPRODUCT('Income Statement'!F29:O29,1/(1+B11)^({1,2,3,4,5,6,7,8,9,10}-Assumptions!C31))+'Income Statement'!O29*(1+G5)/MAX(B11-G5,0.01)/(1+B11)^(10-Assumptions!C31)-(Assumptions!C8-Assumptions!E8))/Assumptions!E7,"—") | H11: =IFERROR(MAX(0,SUMPRODUCT('Income Statement'!F29:O29,1/(1+B11)^({1,2,3,4,5,6,7,8,9,10}-Assumptions!C31))+'Income Statement'!O29*(1+H5)/MAX(B11-H5,0.01)/(1+B11)^(10-Assumptions!C31)-(Assumptions!C8-Assumptions!E8))/Assumptions!E7,"—")
B12: ='DCF Valuation'!C4+(0.015) | C12: =IFERROR(MAX(0,SUMPRODUCT('Income Statement'!F29:O29,1/(1+B12)^({1,2,3,4,5,6,7,8,9,10}-Assumptions!C31))+'Income Statement'!O29*(1+C5)/MAX(B12-C5,0.01)/(1+B12)^(10-Assumptions!C31)-(Assumptions!C8-Assumptions!E8))/Assumptions!E7,"—") | D12: =IFERROR(MAX(0,SUMPRODUCT('Income Statement'!F29:O29,1/(1+B12)^({1,2,3,4,5,6,7,8,9,10}-Assumptions!C31))+'Income Statement'!O29*(1+D5)/MAX(B12-D5,0.01)/(1+B12)^(10-Assumptions!C31)-(Assumptions!C8-Assumptions!E8))/Assumptions!E7,"—") | E12: =IFERROR(MAX(0,SUMPRODUCT('Income Statement'!F29:O29,1/(1+B12)^({1,2,3,4,5,6,7,8,9,10}-Assumptions!C31))+'Income Statement'!O29*(1+E5)/MAX(B12-E5,0.01)/(1+B12)^(10-Assumptions!C31)-(Assumptions!C8-Assumptions!E8))/Assumptions!E7,"—") | F12: =IFERROR(MAX(0,SUMPRODUCT('Income Statement'!F29:O29,1/(1+B12)^({1,2,3,4,5,6,7,8,9,10}-Assumptions!C31))+'Income Statement'!O29*(1+F5)/MAX(B12-F5,0.01)/(1+B12)^(10-Assumptions!C31)-(Assumptions!C8-Assumptions!E8))/Assumptions!E7,"—") | G12: =IFERROR(MAX(0,SUMPRODUCT('Income Statement'!F29:O29,1/(1+B12)^({1,2,3,4,5,6,7,8,9,10}-Assumptions!C31))+'Income Statement'!O29*(1+G5)/MAX(B12-G5,0.01)/(1+B12)^(10-Assumptions!C31)-(Assumptions!C8-Assumptions!E8))/Assumptions!E7,"—") | H12: =IFERROR(MAX(0,SUMPRODUCT('Income Statement'!F29:O29,1/(1+B12)^({1,2,3,4,5,6,7,8,9,10}-Assumptions!C31))+'Income Statement'!O29*(1+H5)/MAX(B12-H5,0.01)/(1+B12)^(10-Assumptions!C31)-(Assumptions!C8-Assumptions!E8))/Assumptions!E7,"—")
B14: TABLE 2 - Implied Share Price vs EBITDA Margin x Uniform Revenue Growth [full DCF re-calc per cell; growth applied to all 10 yrs]
B15: Gr\EBITDA% | C15: =Assumptions!E16+(-0.04) | D15: =Assumptions!E16+(-0.02) | E15: =Assumptions!E16+(0.0) | F15: =Assumptions!E16+(0.02) | G15: =Assumptions!E16+(0.04)
B16: =Assumptions!C10+(-0.03) | C16: =IFERROR(MAX(0,SUMPRODUCT((Assumptions!C28)*(((C15)-(Assumptions!C17))*(1-(Assumptions!E18))+(Assumptions!C17)-(Assumptions!E17)-(Assumptions!C18)*(B16)/(1+(B16))+(Assumptions!C19)*(Assumptions!E31))*(1+(B16))^{1,2,3,4,5,6,7,8,9,10},1/(1+'DCF Valuation'!C4)^({1,2,3,4,5,6,7,8,9,10}-Assumptions!C31))+(Assumptions!C28)*(((C15)-(Assumptions!C17))*(1-(Assumptions!E18))+(Assumptions!C17)-(Assumptions!E17)-(Assumptions!C18)*(B16)/(1+(B16))+(Assumptions!C19)*(Assumptions!E31))*(1+(B16))^10*(1+('DCF Valuation'!C5))/MAX('DCF Valuation'!C4-('DCF Valuation'!C5),0.01)/(1+'DCF Valuation'!C4)^(10-Assumptions!C31)-(Assumptions!C8-Assumptions!E8))/Assumptions!E7,"—") | D16: =IFERROR(MAX(0,SUMPRODUCT((Assumptions!C28)*(((D15)-(Assumptions!C17))*(1-(Assumptions!E18))+(Assumptions!C17)-(Assumptions!E17)-(Assumptions!C18)*(B16)/(1+(B16))+(Assumptions!C19)*(Assumptions!E31))*(1+(B16))^{1,2,3,4,5,6,7,8,9,10},1/(1+'DCF Valuation'!C4)^({1,2,3,4,5,6,7,8,9,10}-Assumptions!C31))+(Assumptions!C28)*(((D15)-(Assumptions!C17))*(1-(Assumptions!E18))+(Assumptions!C17)-(Assumptions!E17)-(Assumptions!C18)*(B16)/(1+(B16))+(Assumptions!C19)*(Assumptions!E31))*(1+(B16))^10*(1+('DCF Valuation'!C5))/MAX('DCF Valuation'!C4-('DCF Valuation'!C5),0.01)/(1+'DCF Valuation'!C4)^(10-Assumptions!C31)-(Assumptions!C8-Assumptions!E8))/Assumptions!E7,"—") | E16: =IFERROR(MAX(0,SUMPRODUCT((Assumptions!C28)*(((E15)-(Assumptions!C17))*(1-(Assumptions!E18))+(Assumptions!C17)-(Assumptions!E17)-(Assumptions!C18)*(B16)/(1+(B16))+(Assumptions!C19)*(Assumptions!E31))*(1+(B16))^{1,2,3,4,5,6,7,8,9,10},1/(1+'DCF Valuation'!C4)^({1,2,3,4,5,6,7,8,9,10}-Assumptions!C31))+(Assumptions!C28)*(((E15)-(Assumptions!C17))*(1-(Assumptions!E18))+(Assumptions!C17)-(Assumptions!E17)-(Assumptions!C18)*(B16)/(1+(B16))+(Assumptions!C19)*(Assumptions!E31))*(1+(B16))^10*(1+('DCF Valuation'!C5))/MAX('DCF Valuation'!C4-('DCF Valuation'!C5),0.01)/(1+'DCF Valuation'!C4)^(10-Assumptions!C31)-(Assumptions!C8-Assumptions!E8))/Assumptions!E7,"—") | F16: =IFERROR(MAX(0,SUMPRODUCT((Assumptions!C28)*(((F15)-(Assumptions!C17))*(1-(Assumptions!E18))+(Assumptions!C17)-(Assumptions!E17)-(Assumptions!C18)*(B16)/(1+(B16))+(Assumptions!C19)*(Assumptions!E31))*(1+(B16))^{1,2,3,4,5,6,7,8,9,10},1/(1+'DCF Valuation'!C4)^({1,2,3,4,5,6,7,8,9,10}-Assumptions!C31))+(Assumptions!C28)*(((F15)-(Assumptions!C17))*(1-(Assumptions!E18))+(Assumptions!C17)-(Assumptions!E17)-(Assumptions!C18)*(B16)/(1+(B16))+(Assumptions!C19)*(Assumptions!E31))*(1+(B16))^10*(1+('DCF Valuation'!C5))/MAX('DCF Valuation'!C4-('DCF Valuation'!C5),0.01)/(1+'DCF Valuation'!C4)^(10-Assumptions!C31)-(Assumptions!C8-Assumptions!E8))/Assumptions!E7,"—") | G16: =IFERROR(MAX(0,SUMPRODUCT((Assumptions!C28)*(((G15)-(Assumptions!C17))*(1-(Assumptions!E18))+(Assumptions!C17)-(Assumptions!E17)-(Assumptions!C18)*(B16)/(1+(B16))+(Assumptions!C19)*(Assumptions!E31))*(1+(B16))^{1,2,3,4,5,6,7,8,9,10},1/(1+'DCF Valuation'!C4)^({1,2,3,4,5,6,7,8,9,10}-Assumptions!C31))+(Assumptions!C28)*(((G15)-(Assumptions!C17))*(1-(Assumptions!E18))+(Assumptions!C17)-(Assumptions!E17)-(Assumptions!C18)*(B16)/(1+(B16))+(Assumptions!C19)*(Assumptions!E31))*(1+(B16))^10*(1+('DCF Valuation'!C5))/MAX('DCF Valuation'!C4-('DCF Valuation'!C5),0.01)/(1+'DCF Valuation'!C4)^(10-Assumptions!C31)-(Assumptions!C8-Assumptions!E8))/Assumptions!E7,"—")
B17: =Assumptions!C10+(-0.02) | C17: =IFERROR(MAX(0,SUMPRODUCT((Assumptions!C28)*(((C15)-(Assumptions!C17))*(1-(Assumptions!E18))+(Assumptions!C17)-(Assumptions!E17)-(Assumptions!C18)*(B17)/(1+(B17))+(Assumptions!C19)*(Assumptions!E31))*(1+(B17))^{1,2,3,4,5,6,7,8,9,10},1/(1+'DCF Valuation'!C4)^({1,2,3,4,5,6,7,8,9,10}-Assumptions!C31))+(Assumptions!C28)*(((C15)-(Assumptions!C17))*(1-(Assumptions!E18))+(Assumptions!C17)-(Assumptions!E17)-(Assumptions!C18)*(B17)/(1+(B17))+(Assumptions!C19)*(Assumptions!E31))*(1+(B17))^10*(1+('DCF Valuation'!C5))/MAX('DCF Valuation'!C4-('DCF Valuation'!C5),0.01)/(1+'DCF Valuation'!C4)^(10-Assumptions!C31)-(Assumptions!C8-Assumptions!E8))/Assumptions!E7,"—") | D17: =IFERROR(MAX(0,SUMPRODUCT((Assumptions!C28)*(((D15)-(Assumptions!C17))*(1-(Assumptions!E18))+(Assumptions!C17)-(Assumptions!E17)-(Assumptions!C18)*(B17)/(1+(B17))+(Assumptions!C19)*(Assumptions!E31))*(1+(B17))^{1,2,3,4,5,6,7,8,9,10},1/(1+'DCF Valuation'!C4)^({1,2,3,4,5,6,7,8,9,10}-Assumptions!C31))+(Assumptions!C28)*(((D15)-(Assumptions!C17))*(1-(Assumptions!E18))+(Assumptions!C17)-(Assumptions!E17)-(Assumptions!C18)*(B17)/(1+(B17))+(Assumptions!C19)*(Assumptions!E31))*(1+(B17))^10*(1+('DCF Valuation'!C5))/MAX('DCF Valuation'!C4-('DCF Valuation'!C5),0.01)/(1+'DCF Valuation'!C4)^(10-Assumptions!C31)-(Assumptions!C8-Assumptions!E8))/Assumptions!E7,"—") | E17: =IFERROR(MAX(0,SUMPRODUCT((Assumptions!C28)*(((E15)-(Assumptions!C17))*(1-(Assumptions!E18))+(Assumptions!C17)-(Assumptions!E17)-(Assumptions!C18)*(B17)/(1+(B17))+(Assumptions!C19)*(Assumptions!E31))*(1+(B17))^{1,2,3,4,5,6,7,8,9,10},1/(1+'DCF Valuation'!C4)^({1,2,3,4,5,6,7,8,9,10}-Assumptions!C31))+(Assumptions!C28)*(((E15)-(Assumptions!C17))*(1-(Assumptions!E18))+(Assumptions!C17)-(Assumptions!E17)-(Assumptions!C18)*(B17)/(1+(B17))+(Assumptions!C19)*(Assumptions!E31))*(1+(B17))^10*(1+('DCF Valuation'!C5))/MAX('DCF Valuation'!C4-('DCF Valuation'!C5),0.01)/(1+'DCF Valuation'!C4)^(10-Assumptions!C31)-(Assumptions!C8-Assumptions!E8))/Assumptions!E7,"—") | F17: =IFERROR(MAX(0,SUMPRODUCT((Assumptions!C28)*(((F15)-(Assumptions!C17))*(1-(Assumptions!E18))+(Assumptions!C17)-(Assumptions!E17)-(Assumptions!C18)*(B17)/(1+(B17))+(Assumptions!C19)*(Assumptions!E31))*(1+(B17))^{1,2,3,4,5,6,7,8,9,10},1/(1+'DCF Valuation'!C4)^({1,2,3,4,5,6,7,8,9,10}-Assumptions!C31))+(Assumptions!C28)*(((F15)-(Assumptions!C17))*(1-(Assumptions!E18))+(Assumptions!C17)-(Assumptions!E17)-(Assumptions!C18)*(B17)/(1+(B17))+(Assumptions!C19)*(Assumptions!E31))*(1+(B17))^10*(1+('DCF Valuation'!C5))/MAX('DCF Valuation'!C4-('DCF Valuation'!C5),0.01)/(1+'DCF Valuation'!C4)^(10-Assumptions!C31)-(Assumptions!C8-Assumptions!E8))/Assumptions!E7,"—") | G17: =IFERROR(MAX(0,SUMPRODUCT((Assumptions!C28)*(((G15)-(Assumptions!C17))*(1-(Assumptions!E18))+(Assumptions!C17)-(Assumptions!E17)-(Assumptions!C18)*(B17)/(1+(B17))+(Assumptions!C19)*(Assumptions!E31))*(1+(B17))^{1,2,3,4,5,6,7,8,9,10},1/(1+'DCF Valuation'!C4)^({1,2,3,4,5,6,7,8,9,10}-Assumptions!C31))+(Assumptions!C28)*(((G15)-(Assumptions!C17))*(1-(Assumptions!E18))+(Assumptions!C17)-(Assumptions!E17)-(Assumptions!C18)*(B17)/(1+(B17))+(Assumptions!C19)*(Assumptions!E31))*(1+(B17))^10*(1+('DCF Valuation'!C5))/MAX('DCF Valuation'!C4-('DCF Valuation'!C5),0.01)/(1+'DCF Valuation'!C4)^(10-Assumptions!C31)-(Assumptions!C8-Assumptions!E8))/Assumptions!E7,"—")
B18: =Assumptions!C10+(-0.01) | C18: =IFERROR(MAX(0,SUMPRODUCT((Assumptions!C28)*(((C15)-(Assumptions!C17))*(1-(Assumptions!E18))+(Assumptions!C17)-(Assumptions!E17)-(Assumptions!C18)*(B18)/(1+(B18))+(Assumptions!C19)*(Assumptions!E31))*(1+(B18))^{1,2,3,4,5,6,7,8,9,10},1/(1+'DCF Valuation'!C4)^({1,2,3,4,5,6,7,8,9,10}-Assumptions!C31))+(Assumptions!C28)*(((C15)-(Assumptions!C17))*(1-(Assumptions!E18))+(Assumptions!C17)-(Assumptions!E17)-(Assumptions!C18)*(B18)/(1+(B18))+(Assumptions!C19)*(Assumptions!E31))*(1+(B18))^10*(1+('DCF Valuation'!C5))/MAX('DCF Valuation'!C4-('DCF Valuation'!C5),0.01)/(1+'DCF Valuation'!C4)^(10-Assumptions!C31)-(Assumptions!C8-Assumptions!E8))/Assumptions!E7,"—") | D18: =IFERROR(MAX(0,SUMPRODUCT((Assumptions!C28)*(((D15)-(Assumptions!C17))*(1-(Assumptions!E18))+(Assumptions!C17)-(Assumptions!E17)-(Assumptions!C18)*(B18)/(1+(B18))+(Assumptions!C19)*(Assumptions!E31))*(1+(B18))^{1,2,3,4,5,6,7,8,9,10},1/(1+'DCF Valuation'!C4)^({1,2,3,4,5,6,7,8,9,10}-Assumptions!C31))+(Assumptions!C28)*(((D15)-(Assumptions!C17))*(1-(Assumptions!E18))+(Assumptions!C17)-(Assumptions!E17)-(Assumptions!C18)*(B18)/(1+(B18))+(Assumptions!C19)*(Assumptions!E31))*(1+(B18))^10*(1+('DCF Valuation'!C5))/MAX('DCF Valuation'!C4-('DCF Valuation'!C5),0.01)/(1+'DCF Valuation'!C4)^(10-Assumptions!C31)-(Assumptions!C8-Assumptions!E8))/Assumptions!E7,"—") | E18: =IFERROR(MAX(0,SUMPRODUCT((Assumptions!C28)*(((E15)-(Assumptions!C17))*(1-(Assumptions!E18))+(Assumptions!C17)-(Assumptions!E17)-(Assumptions!C18)*(B18)/(1+(B18))+(Assumptions!C19)*(Assumptions!E31))*(1+(B18))^{1,2,3,4,5,6,7,8,9,10},1/(1+'DCF Valuation'!C4)^({1,2,3,4,5,6,7,8,9,10}-Assumptions!C31))+(Assumptions!C28)*(((E15)-(Assumptions!C17))*(1-(Assumptions!E18))+(Assumptions!C17)-(Assumptions!E17)-(Assumptions!C18)*(B18)/(1+(B18))+(Assumptions!C19)*(Assumptions!E31))*(1+(B18))^10*(1+('DCF Valuation'!C5))/MAX('DCF Valuation'!C4-('DCF Valuation'!C5),0.01)/(1+'DCF Valuation'!C4)^(10-Assumptions!C31)-(Assumptions!C8-Assumptions!E8))/Assumptions!E7,"—") | F18: =IFERROR(MAX(0,SUMPRODUCT((Assumptions!C28)*(((F15)-(Assumptions!C17))*(1-(Assumptions!E18))+(Assumptions!C17)-(Assumptions!E17)-(Assumptions!C18)*(B18)/(1+(B18))+(Assumptions!C19)*(Assumptions!E31))*(1+(B18))^{1,2,3,4,5,6,7,8,9,10},1/(1+'DCF Valuation'!C4)^({1,2,3,4,5,6,7,8,9,10}-Assumptions!C31))+(Assumptions!C28)*(((F15)-(Assumptions!C17))*(1-(Assumptions!E18))+(Assumptions!C17)-(Assumptions!E17)-(Assumptions!C18)*(B18)/(1+(B18))+(Assumptions!C19)*(Assumptions!E31))*(1+(B18))^10*(1+('DCF Valuation'!C5))/MAX('DCF Valuation'!C4-('DCF Valuation'!C5),0.01)/(1+'DCF Valuation'!C4)^(10-Assumptions!C31)-(Assumptions!C8-Assumptions!E8))/Assumptions!E7,"—") | G18: =IFERROR(MAX(0,SUMPRODUCT((Assumptions!C28)*(((G15)-(Assumptions!C17))*(1-(Assumptions!E18))+(Assumptions!C17)-(Assumptions!E17)-(Assumptions!C18)*(B18)/(1+(B18))+(Assumptions!C19)*(Assumptions!E31))*(1+(B18))^{1,2,3,4,5,6,7,8,9,10},1/(1+'DCF Valuation'!C4)^({1,2,3,4,5,6,7,8,9,10}-Assumptions!C31))+(Assumptions!C28)*(((G15)-(Assumptions!C17))*(1-(Assumptions!E18))+(Assumptions!C17)-(Assumptions!E17)-(Assumptions!C18)*(B18)/(1+(B18))+(Assumptions!C19)*(Assumptions!E31))*(1+(B18))^10*(1+('DCF Valuation'!C5))/MAX('DCF Valuation'!C4-('DCF Valuation'!C5),0.01)/(1+'DCF Valuation'!C4)^(10-Assumptions!C31)-(Assumptions!C8-Assumptions!E8))/Assumptions!E7,"—")
B19: =Assumptions!C10+(0.0) | C19: =IFERROR(MAX(0,SUMPRODUCT((Assumptions!C28)*(((C15)-(Assumptions!C17))*(1-(Assumptions!E18))+(Assumptions!C17)-(Assumptions!E17)-(Assumptions!C18)*(B19)/(1+(B19))+(Assumptions!C19)*(Assumptions!E31))*(1+(B19))^{1,2,3,4,5,6,7,8,9,10},1/(1+'DCF Valuation'!C4)^({1,2,3,4,5,6,7,8,9,10}-Assumptions!C31))+(Assumptions!C28)*(((C15)-(Assumptions!C17))*(1-(Assumptions!E18))+(Assumptions!C17)-(Assumptions!E17)-(Assumptions!C18)*(B19)/(1+(B19))+(Assumptions!C19)*(Assumptions!E31))*(1+(B19))^10*(1+('DCF Valuation'!C5))/MAX('DCF Valuation'!C4-('DCF Valuation'!C5),0.01)/(1+'DCF Valuation'!C4)^(10-Assumptions!C31)-(Assumptions!C8-Assumptions!E8))/Assumptions!E7,"—") | D19: =IFERROR(MAX(0,SUMPRODUCT((Assumptions!C28)*(((D15)-(Assumptions!C17))*(1-(Assumptions!E18))+(Assumptions!C17)-(Assumptions!E17)-(Assumptions!C18)*(B19)/(1+(B19))+(Assumptions!C19)*(Assumptions!E31))*(1+(B19))^{1,2,3,4,5,6,7,8,9,10},1/(1+'DCF Valuation'!C4)^({1,2,3,4,5,6,7,8,9,10}-Assumptions!C31))+(Assumptions!C28)*(((D15)-(Assumptions!C17))*(1-(Assumptions!E18))+(Assumptions!C17)-(Assumptions!E17)-(Assumptions!C18)*(B19)/(1+(B19))+(Assumptions!C19)*(Assumptions!E31))*(1+(B19))^10*(1+('DCF Valuation'!C5))/MAX('DCF Valuation'!C4-('DCF Valuation'!C5),0.01)/(1+'DCF Valuation'!C4)^(10-Assumptions!C31)-(Assumptions!C8-Assumptions!E8))/Assumptions!E7,"—") | E19: =IFERROR(MAX(0,SUMPRODUCT((Assumptions!C28)*(((E15)-(Assumptions!C17))*(1-(Assumptions!E18))+(Assumptions!C17)-(Assumptions!E17)-(Assumptions!C18)*(B19)/(1+(B19))+(Assumptions!C19)*(Assumptions!E31))*(1+(B19))^{1,2,3,4,5,6,7,8,9,10},1/(1+'DCF Valuation'!C4)^({1,2,3,4,5,6,7,8,9,10}-Assumptions!C31))+(Assumptions!C28)*(((E15)-(Assumptions!C17))*(1-(Assumptions!E18))+(Assumptions!C17)-(Assumptions!E17)-(Assumptions!C18)*(B19)/(1+(B19))+(Assumptions!C19)*(Assumptions!E31))*(1+(B19))^10*(1+('DCF Valuation'!C5))/MAX('DCF Valuation'!C4-('DCF Valuation'!C5),0.01)/(1+'DCF Valuation'!C4)^(10-Assumptions!C31)-(Assumptions!C8-Assumptions!E8))/Assumptions!E7,"—") | F19: =IFERROR(MAX(0,SUMPRODUCT((Assumptions!C28)*(((F15)-(Assumptions!C17))*(1-(Assumptions!E18))+(Assumptions!C17)-(Assumptions!E17)-(Assumptions!C18)*(B19)/(1+(B19))+(Assumptions!C19)*(Assumptions!E31))*(1+(B19))^{1,2,3,4,5,6,7,8,9,10},1/(1+'DCF Valuation'!C4)^({1,2,3,4,5,6,7,8,9,10}-Assumptions!C31))+(Assumptions!C28)*(((F15)-(Assumptions!C17))*(1-(Assumptions!E18))+(Assumptions!C17)-(Assumptions!E17)-(Assumptions!C18)*(B19)/(1+(B19))+(Assumptions!C19)*(Assumptions!E31))*(1+(B19))^10*(1+('DCF Valuation'!C5))/MAX('DCF Valuation'!C4-('DCF Valuation'!C5),0.01)/(1+'DCF Valuation'!C4)^(10-Assumptions!C31)-(Assumptions!C8-Assumptions!E8))/Assumptions!E7,"—") | G19: =IFERROR(MAX(0,SUMPRODUCT((Assumptions!C28)*(((G15)-(Assumptions!C17))*(1-(Assumptions!E18))+(Assumptions!C17)-(Assumptions!E17)-(Assumptions!C18)*(B19)/(1+(B19))+(Assumptions!C19)*(Assumptions!E31))*(1+(B19))^{1,2,3,4,5,6,7,8,9,10},1/(1+'DCF Valuation'!C4)^({1,2,3,4,5,6,7,8,9,10}-Assumptions!C31))+(Assumptions!C28)*(((G15)-(Assumptions!C17))*(1-(Assumptions!E18))+(Assumptions!C17)-(Assumptions!E17)-(Assumptions!C18)*(B19)/(1+(B19))+(Assumptions!C19)*(Assumptions!E31))*(1+(B19))^10*(1+('DCF Valuation'!C5))/MAX('DCF Valuation'!C4-('DCF Valuation'!C5),0.01)/(1+'DCF Valuation'!C4)^(10-Assumptions!C31)-(Assumptions!C8-Assumptions!E8))/Assumptions!E7,"—")
B20: =Assumptions!C10+(0.01) | C20: =IFERROR(MAX(0,SUMPRODUCT((Assumptions!C28)*(((C15)-(Assumptions!C17))*(1-(Assumptions!E18))+(Assumptions!C17)-(Assumptions!E17)-(Assumptions!C18)*(B20)/(1+(B20))+(Assumptions!C19)*(Assumptions!E31))*(1+(B20))^{1,2,3,4,5,6,7,8,9,10},1/(1+'DCF Valuation'!C4)^({1,2,3,4,5,6,7,8,9,10}-Assumptions!C31))+(Assumptions!C28)*(((C15)-(Assumptions!C17))*(1-(Assumptions!E18))+(Assumptions!C17)-(Assumptions!E17)-(Assumptions!C18)*(B20)/(1+(B20))+(Assumptions!C19)*(Assumptions!E31))*(1+(B20))^10*(1+('DCF Valuation'!C5))/MAX('DCF Valuation'!C4-('DCF Valuation'!C5),0.01)/(1+'DCF Valuation'!C4)^(10-Assumptions!C31)-(Assumptions!C8-Assumptions!E8))/Assumptions!E7,"—") | D20: =IFERROR(MAX(0,SUMPRODUCT((Assumptions!C28)*(((D15)-(Assumptions!C17))*(1-(Assumptions!E18))+(Assumptions!C17)-(Assumptions!E17)-(Assumptions!C18)*(B20)/(1+(B20))+(Assumptions!C19)*(Assumptions!E31))*(1+(B20))^{1,2,3,4,5,6,7,8,9,10},1/(1+'DCF Valuation'!C4)^({1,2,3,4,5,6,7,8,9,10}-Assumptions!C31))+(Assumptions!C28)*(((D15)-(Assumptions!C17))*(1-(Assumptions!E18))+(Assumptions!C17)-(Assumptions!E17)-(Assumptions!C18)*(B20)/(1+(B20))+(Assumptions!C19)*(Assumptions!E31))*(1+(B20))^10*(1+('DCF Valuation'!C5))/MAX('DCF Valuation'!C4-('DCF Valuation'!C5),0.01)/(1+'DCF Valuation'!C4)^(10-Assumptions!C31)-(Assumptions!C8-Assumptions!E8))/Assumptions!E7,"—") | E20: =IFERROR(MAX(0,SUMPRODUCT((Assumptions!C28)*(((E15)-(Assumptions!C17))*(1-(Assumptions!E18))+(Assumptions!C17)-(Assumptions!E17)-(Assumptions!C18)*(B20)/(1+(B20))+(Assumptions!C19)*(Assumptions!E31))*(1+(B20))^{1,2,3,4,5,6,7,8,9,10},1/(1+'DCF Valuation'!C4)^({1,2,3,4,5,6,7,8,9,10}-Assumptions!C31))+(Assumptions!C28)*(((E15)-(Assumptions!C17))*(1-(Assumptions!E18))+(Assumptions!C17)-(Assumptions!E17)-(Assumptions!C18)*(B20)/(1+(B20))+(Assumptions!C19)*(Assumptions!E31))*(1+(B20))^10*(1+('DCF Valuation'!C5))/MAX('DCF Valuation'!C4-('DCF Valuation'!C5),0.01)/(1+'DCF Valuation'!C4)^(10-Assumptions!C31)-(Assumptions!C8-Assumptions!E8))/Assumptions!E7,"—") | F20: =IFERROR(MAX(0,SUMPRODUCT((Assumptions!C28)*(((F15)-(Assumptions!C17))*(1-(Assumptions!E18))+(Assumptions!C17)-(Assumptions!E17)-(Assumptions!C18)*(B20)/(1+(B20))+(Assumptions!C19)*(Assumptions!E31))*(1+(B20))^{1,2,3,4,5,6,7,8,9,10},1/(1+'DCF Valuation'!C4)^({1,2,3,4,5,6,7,8,9,10}-Assumptions!C31))+(Assumptions!C28)*(((F15)-(Assumptions!C17))*(1-(Assumptions!E18))+(Assumptions!C17)-(Assumptions!E17)-(Assumptions!C18)*(B20)/(1+(B20))+(Assumptions!C19)*(Assumptions!E31))*(1+(B20))^10*(1+('DCF Valuation'!C5))/MAX('DCF Valuation'!C4-('DCF Valuation'!C5),0.01)/(1+'DCF Valuation'!C4)^(10-Assumptions!C31)-(Assumptions!C8-Assumptions!E8))/Assumptions!E7,"—") | G20: =IFERROR(MAX(0,SUMPRODUCT((Assumptions!C28)*(((G15)-(Assumptions!C17))*(1-(Assumptions!E18))+(Assumptions!C17)-(Assumptions!E17)-(Assumptions!C18)*(B20)/(1+(B20))+(Assumptions!C19)*(Assumptions!E31))*(1+(B20))^{1,2,3,4,5,6,7,8,9,10},1/(1+'DCF Valuation'!C4)^({1,2,3,4,5,6,7,8,9,10}-Assumptions!C31))+(Assumptions!C28)*(((G15)-(Assumptions!C17))*(1-(Assumptions!E18))+(Assumptions!C17)-(Assumptions!E17)-(Assumptions!C18)*(B20)/(1+(B20))+(Assumptions!C19)*(Assumptions!E31))*(1+(B20))^10*(1+('DCF Valuation'!C5))/MAX('DCF Valuation'!C4-('DCF Valuation'!C5),0.01)/(1+'DCF Valuation'!C4)^(10-Assumptions!C31)-(Assumptions!C8-Assumptions!E8))/Assumptions!E7,"—")
B21: =Assumptions!C10+(0.02) | C21: =IFERROR(MAX(0,SUMPRODUCT((Assumptions!C28)*(((C15)-(Assumptions!C17))*(1-(Assumptions!E18))+(Assumptions!C17)-(Assumptions!E17)-(Assumptions!C18)*(B21)/(1+(B21))+(Assumptions!C19)*(Assumptions!E31))*(1+(B21))^{1,2,3,4,5,6,7,8,9,10},1/(1+'DCF Valuation'!C4)^({1,2,3,4,5,6,7,8,9,10}-Assumptions!C31))+(Assumptions!C28)*(((C15)-(Assumptions!C17))*(1-(Assumptions!E18))+(Assumptions!C17)-(Assumptions!E17)-(Assumptions!C18)*(B21)/(1+(B21))+(Assumptions!C19)*(Assumptions!E31))*(1+(B21))^10*(1+('DCF Valuation'!C5))/MAX('DCF Valuation'!C4-('DCF Valuation'!C5),0.01)/(1+'DCF Valuation'!C4)^(10-Assumptions!C31)-(Assumptions!C8-Assumptions!E8))/Assumptions!E7,"—") | D21: =IFERROR(MAX(0,SUMPRODUCT((Assumptions!C28)*(((D15)-(Assumptions!C17))*(1-(Assumptions!E18))+(Assumptions!C17)-(Assumptions!E17)-(Assumptions!C18)*(B21)/(1+(B21))+(Assumptions!C19)*(Assumptions!E31))*(1+(B21))^{1,2,3,4,5,6,7,8,9,10},1/(1+'DCF Valuation'!C4)^({1,2,3,4,5,6,7,8,9,10}-Assumptions!C31))+(Assumptions!C28)*(((D15)-(Assumptions!C17))*(1-(Assumptions!E18))+(Assumptions!C17)-(Assumptions!E17)-(Assumptions!C18)*(B21)/(1+(B21))+(Assumptions!C19)*(Assumptions!E31))*(1+(B21))^10*(1+('DCF Valuation'!C5))/MAX('DCF Valuation'!C4-('DCF Valuation'!C5),0.01)/(1+'DCF Valuation'!C4)^(10-Assumptions!C31)-(Assumptions!C8-Assumptions!E8))/Assumptions!E7,"—") | E21: =IFERROR(MAX(0,SUMPRODUCT((Assumptions!C28)*(((E15)-(Assumptions!C17))*(1-(Assumptions!E18))+(Assumptions!C17)-(Assumptions!E17)-(Assumptions!C18)*(B21)/(1+(B21))+(Assumptions!C19)*(Assumptions!E31))*(1+(B21))^{1,2,3,4,5,6,7,8,9,10},1/(1+'DCF Valuation'!C4)^({1,2,3,4,5,6,7,8,9,10}-Assumptions!C31))+(Assumptions!C28)*(((E15)-(Assumptions!C17))*(1-(Assumptions!E18))+(Assumptions!C17)-(Assumptions!E17)-(Assumptions!C18)*(B21)/(1+(B21))+(Assumptions!C19)*(Assumptions!E31))*(1+(B21))^10*(1+('DCF Valuation'!C5))/MAX('DCF Valuation'!C4-('DCF Valuation'!C5),0.01)/(1+'DCF Valuation'!C4)^(10-Assumptions!C31)-(Assumptions!C8-Assumptions!E8))/Assumptions!E7,"—") | F21: =IFERROR(MAX(0,SUMPRODUCT((Assumptions!C28)*(((F15)-(Assumptions!C17))*(1-(Assumptions!E18))+(Assumptions!C17)-(Assumptions!E17)-(Assumptions!C18)*(B21)/(1+(B21))+(Assumptions!C19)*(Assumptions!E31))*(1+(B21))^{1,2,3,4,5,6,7,8,9,10},1/(1+'DCF Valuation'!C4)^({1,2,3,4,5,6,7,8,9,10}-Assumptions!C31))+(Assumptions!C28)*(((F15)-(Assumptions!C17))*(1-(Assumptions!E18))+(Assumptions!C17)-(Assumptions!E17)-(Assumptions!C18)*(B21)/(1+(B21))+(Assumptions!C19)*(Assumptions!E31))*(1+(B21))^10*(1+('DCF Valuation'!C5))/MAX('DCF Valuation'!C4-('DCF Valuation'!C5),0.01)/(1+'DCF Valuation'!C4)^(10-Assumptions!C31)-(Assumptions!C8-Assumptions!E8))/Assumptions!E7,"—") | G21: =IFERROR(MAX(0,SUMPRODUCT((Assumptions!C28)*(((G15)-(Assumptions!C17))*(1-(Assumptions!E18))+(Assumptions!C17)-(Assumptions!E17)-(Assumptions!C18)*(B21)/(1+(B21))+(Assumptions!C19)*(Assumptions!E31))*(1+(B21))^{1,2,3,4,5,6,7,8,9,10},1/(1+'DCF Valuation'!C4)^({1,2,3,4,5,6,7,8,9,10}-Assumptions!C31))+(Assumptions!C28)*(((G15)-(Assumptions!C17))*(1-(Assumptions!E18))+(Assumptions!C17)-(Assumptions!E17)-(Assumptions!C18)*(B21)/(1+(B21))+(Assumptions!C19)*(Assumptions!E31))*(1+(B21))^10*(1+('DCF Valuation'!C5))/MAX('DCF Valuation'!C4-('DCF Valuation'!C5),0.01)/(1+'DCF Valuation'!C4)^(10-Assumptions!C31)-(Assumptions!C8-Assumptions!E8))/Assumptions!E7,"—")
B22: =Assumptions!C10+(0.03) | C22: =IFERROR(MAX(0,SUMPRODUCT((Assumptions!C28)*(((C15)-(Assumptions!C17))*(1-(Assumptions!E18))+(Assumptions!C17)-(Assumptions!E17)-(Assumptions!C18)*(B22)/(1+(B22))+(Assumptions!C19)*(Assumptions!E31))*(1+(B22))^{1,2,3,4,5,6,7,8,9,10},1/(1+'DCF Valuation'!C4)^({1,2,3,4,5,6,7,8,9,10}-Assumptions!C31))+(Assumptions!C28)*(((C15)-(Assumptions!C17))*(1-(Assumptions!E18))+(Assumptions!C17)-(Assumptions!E17)-(Assumptions!C18)*(B22)/(1+(B22))+(Assumptions!C19)*(Assumptions!E31))*(1+(B22))^10*(1+('DCF Valuation'!C5))/MAX('DCF Valuation'!C4-('DCF Valuation'!C5),0.01)/(1+'DCF Valuation'!C4)^(10-Assumptions!C31)-(Assumptions!C8-Assumptions!E8))/Assumptions!E7,"—") | D22: =IFERROR(MAX(0,SUMPRODUCT((Assumptions!C28)*(((D15)-(Assumptions!C17))*(1-(Assumptions!E18))+(Assumptions!C17)-(Assumptions!E17)-(Assumptions!C18)*(B22)/(1+(B22))+(Assumptions!C19)*(Assumptions!E31))*(1+(B22))^{1,2,3,4,5,6,7,8,9,10},1/(1+'DCF Valuation'!C4)^({1,2,3,4,5,6,7,8,9,10}-Assumptions!C31))+(Assumptions!C28)*(((D15)-(Assumptions!C17))*(1-(Assumptions!E18))+(Assumptions!C17)-(Assumptions!E17)-(Assumptions!C18)*(B22)/(1+(B22))+(Assumptions!C19)*(Assumptions!E31))*(1+(B22))^10*(1+('DCF Valuation'!C5))/MAX('DCF Valuation'!C4-('DCF Valuation'!C5),0.01)/(1+'DCF Valuation'!C4)^(10-Assumptions!C31)-(Assumptions!C8-Assumptions!E8))/Assumptions!E7,"—") | E22: =IFERROR(MAX(0,SUMPRODUCT((Assumptions!C28)*(((E15)-(Assumptions!C17))*(1-(Assumptions!E18))+(Assumptions!C17)-(Assumptions!E17)-(Assumptions!C18)*(B22)/(1+(B22))+(Assumptions!C19)*(Assumptions!E31))*(1+(B22))^{1,2,3,4,5,6,7,8,9,10},1/(1+'DCF Valuation'!C4)^({1,2,3,4,5,6,7,8,9,10}-Assumptions!C31))+(Assumptions!C28)*(((E15)-(Assumptions!C17))*(1-(Assumptions!E18))+(Assumptions!C17)-(Assumptions!E17)-(Assumptions!C18)*(B22)/(1+(B22))+(Assumptions!C19)*(Assumptions!E31))*(1+(B22))^10*(1+('DCF Valuation'!C5))/MAX('DCF Valuation'!C4-('DCF Valuation'!C5),0.01)/(1+'DCF Valuation'!C4)^(10-Assumptions!C31)-(Assumptions!C8-Assumptions!E8))/Assumptions!E7,"—") | F22: =IFERROR(MAX(0,SUMPRODUCT((Assumptions!C28)*(((F15)-(Assumptions!C17))*(1-(Assumptions!E18))+(Assumptions!C17)-(Assumptions!E17)-(Assumptions!C18)*(B22)/(1+(B22))+(Assumptions!C19)*(Assumptions!E31))*(1+(B22))^{1,2,3,4,5,6,7,8,9,10},1/(1+'DCF Valuation'!C4)^({1,2,3,4,5,6,7,8,9,10}-Assumptions!C31))+(Assumptions!C28)*(((F15)-(Assumptions!C17))*(1-(Assumptions!E18))+(Assumptions!C17)-(Assumptions!E17)-(Assumptions!C18)*(B22)/(1+(B22))+(Assumptions!C19)*(Assumptions!E31))*(1+(B22))^10*(1+('DCF Valuation'!C5))/MAX('DCF Valuation'!C4-('DCF Valuation'!C5),0.01)/(1+'DCF Valuation'!C4)^(10-Assumptions!C31)-(Assumptions!C8-Assumptions!E8))/Assumptions!E7,"—") | G22: =IFERROR(MAX(0,SUMPRODUCT((Assumptions!C28)*(((G15)-(Assumptions!C17))*(1-(Assumptions!E18))+(Assumptions!C17)-(Assumptions!E17)-(Assumptions!C18)*(B22)/(1+(B22))+(Assumptions!C19)*(Assumptions!E31))*(1+(B22))^{1,2,3,4,5,6,7,8,9,10},1/(1+'DCF Valuation'!C4)^({1,2,3,4,5,6,7,8,9,10}-Assumptions!C31))+(Assumptions!C28)*(((G15)-(Assumptions!C17))*(1-(Assumptions!E18))+(Assumptions!C17)-(Assumptions!E17)-(Assumptions!C18)*(B22)/(1+(B22))+(Assumptions!C19)*(Assumptions!E31))*(1+(B22))^10*(1+('DCF Valuation'!C5))/MAX('DCF Valuation'!C4-('DCF Valuation'!C5),0.01)/(1+'DCF Valuation'!C4)^(10-Assumptions!C31)-(Assumptions!C8-Assumptions!E8))/Assumptions!E7,"—")
B24: FOOTBALL FIELD - Valuation Range Summary
B25: Method | C25: Low ($) | D25: High ($) | E25: Current ($) | F25: Notes
B26: DCF (base case) | C26: ='DCF Valuation'!C26 | D26: ='DCF Valuation'!C26 | E26: =Assumptions!C7 | F26: Gordon Growth TV
B27: DCF scenarios (Bear→Bull) | C27: =Scenarios!C18 | D27: =Scenarios!E18 | E27: =Assumptions!C7 | F27: Linked from Scenarios sheet
B28: EV/EBITDA (18-22x fwd) | C28: ='Income Statement'!O13*(1+'DCF Valuation'!C5)*18/Assumptions!E7 | D28: ='Income Statement'!O13*(1+'DCF Valuation'!C5)*22/Assumptions!E7 | E28: =Assumptions!C7 | F28: Forward EBITDA × multiple
B29: Current price (mkt) | C29: =Assumptions!C7 | D29: =Assumptions!C7 | E29: =Assumptions!C7 | F29: Market quote

Sheet Scenarios
B1: SCENARIO ANALYSIS - Bear / Base / Bull
B2: Edit gold cells for Bear and Bull cases. Base links from Assumptions. Implied prices auto-calculate.
B4: ASSUMPTION | C4: BEAR | D4: BASE | E4: BULL
B5: REVENUE GROWTH
B6: Y1-Y5 Revenue Growth (avg) | C6: =MAX((Assumptions!C10+Assumptions!E10+Assumptions!C11+Assumptions!E11+Assumptions!C12)/5-0.03,Assumptions!C26) | D6: =(Assumptions!C10+Assumptions!E10+Assumptions!C11+Assumptions!E11+Assumptions!C12)/5 | E6: =MIN((Assumptions!C10+Assumptions!E10+Assumptions!C11+Assumptions!E11+Assumptions!C12)/5+0.04,0.80)
B7: Y6-Y10 Revenue Growth (avg) | C7: =MAX((Assumptions!E12+Assumptions!C13+Assumptions!E13+Assumptions!C14+Assumptions!E14)/5-0.02,Assumptions!C26) | D7: =(Assumptions!E12+Assumptions!C13+Assumptions!E13+Assumptions!C14+Assumptions!E14)/5 | E7: =MIN((Assumptions!E12+Assumptions!C13+Assumptions!E13+Assumptions!C14+Assumptions!E14)/5+0.03,0.60)
B8: MARGIN & DISCOUNT RATE
B9: EBITDA Margin % | C9: =MAX(Assumptions!E16-0.05,0.03) | D9: =Assumptions!E16 | E9: =MIN(Assumptions!E16+0.08,0.85)
B10: FCF Margin (% of Revenue) | C10: =MAX(0,(C9-Assumptions!C17)*(1-Assumptions!E18)+Assumptions!C17-Assumptions!E17-Assumptions!C18+Assumptions!C19*Assumptions!E31) | D10: =MAX(0,(D9-Assumptions!C17)*(1-Assumptions!E18)+Assumptions!C17-Assumptions!E17-Assumptions!C18+Assumptions!C19*Assumptions!E31) | E10: =MAX(0,(E9-Assumptions!C17)*(1-Assumptions!E18)+Assumptions!C17-Assumptions!E17-Assumptions!C18+Assumptions!C19*Assumptions!E31)
B11: WACC | C11: 0.11 | D11: =WACC!E17 | E11: 0.08
B12: Terminal Growth Rate | C12: 0.02 | D12: =Assumptions!C26 | E12: 0.03
B13: COMMON INPUTS (linked from model)
B14: Base Revenue Y0 ($M) | C14: =Assumptions!C28 | D14: =Assumptions!C28 | E14: =Assumptions!C28
B15: Net Debt ($M) | C15: =Assumptions!C8-Assumptions!E8 | D15: =Assumptions!C8-Assumptions!E8 | E15: =Assumptions!C8-Assumptions!E8
B16: Shares Outstanding (M) | C16: =Assumptions!E7 | D16: =Assumptions!E7 | E16: =Assumptions!E7
B17: VALUATION OUTPUT
B18: IMPLIED SHARE PRICE | C18: =IFERROR(MAX(0,SUMPRODUCT(C14*C10*(1+C6)^{1,2,3,4,5},1/(1+C11)^({1,2,3,4,5}-Assumptions!C31))+SUMPRODUCT(C14*C10*(1+C6)^5*(1+C7)^{1,2,3,4,5},1/(1+C11)^({6,7,8,9,10}-Assumptions!C31))+C14*C10*(1+C6)^5*(1+C7)^5*(1+C12)/MAX(C11-C12,0.01)/(1+C11)^(10-Assumptions!C31)-C15)/C16,"--") | D18: =IFERROR(MAX(0,SUMPRODUCT(D14*D10*(1+D6)^{1,2,3,4,5},1/(1+D11)^({1,2,3,4,5}-Assumptions!C31))+SUMPRODUCT(D14*D10*(1+D6)^5*(1+D7)^{1,2,3,4,5},1/(1+D11)^({6,7,8,9,10}-Assumptions!C31))+D14*D10*(1+D6)^5*(1+D7)^5*(1+D12)/MAX(D11-D12,0.01)/(1+D11)^(10-Assumptions!C31)-D15)/D16,"--") | E18: =IFERROR(MAX(0,SUMPRODUCT(E14*E10*(1+E6)^{1,2,3,4,5},1/(1+E11)^({1,2,3,4,5}-Assumptions!C31))+SUMPRODUCT(E14*E10*(1+E6)^5*(1+E7)^{1,2,3,4,5},1/(1+E11)^({6,7,8,9,10}-Assumptions!C31))+E14*E10*(1+E6)^5*(1+E7)^5*(1+E12)/MAX(E11-E12,0.01)/(1+E11)^(10-Assumptions!C31)-E15)/E16,"--")
B19: Current Market Price ($) | C19: =Assumptions!C7 | D19: =Assumptions!C7 | E19: =Assumptions!C7
B20: Upside / (Downside) % | C20: =IFERROR((C18-D19)/D19,"--") | D20: =IFERROR((D18-D19)/D19,"--") | E20: =IFERROR((E18-D19)/D19,"--")
B22: EXPECTED VALUE SUMMARY
B23: Equal-Weighted Avg Price ($) | C23: =IFERROR((C18+D18+E18)/3,"--")
B24: Expected Upside / (Downside) % | C24: =IFERROR((C23-D19)/D19,"--")

Sheet Reverse DCF
B1: REVERSE DCF - Implied Growth Rate at Current Price
B2: Find the column where implied price = current market price. That growth rate is what the market is pricing in. Range: 2% - 60% to cover both mature and high-growth companies.
B4: Target / Market Price ($) | D4: =Assumptions!C7 | E4: Edit D4 to test any price. Green = implied price >= D4 (potential buy).
B5: FCF Margin (model-derived) | D5: =MAX(0,(Assumptions!E16-Assumptions!C17)*(1-Assumptions!E18)+Assumptions!C17-Assumptions!E17-Assumptions!C18+Assumptions!C19*Assumptions!E31) | E5: Flows from Assumptions — edit margins there to see impact here.
B6: Terminal Growth Rate | D6: ='DCF Valuation'!C5
B8: TABLE: Implied Share Price by Uniform Revenue Growth Rate x WACC -- find where implied price = market price
B9: WACC \ Growth | C9: 0.02 | D9: 0.05 | E9: 0.1 | F9: 0.15 | G9: 0.2 | H9: 0.25 | I9: 0.3 | J9: 0.4 | K9: 0.5 | L9: 0.6
B10: ='DCF Valuation'!C4+(-0.015) | C10: =IFERROR(MAX(0,SUMPRODUCT(Assumptions!C28*D5*(1+C9)^{1,2,3,4,5,6,7,8,9,10},1/(1+B10)^({1,2,3,4,5,6,7,8,9,10}-Assumptions!C31))+Assumptions!C28*D5*(1+C9)^10*(1+D6)/MAX(B10-D6,0.01)/(1+B10)^(10-Assumptions!C31)-(Assumptions!C8-Assumptions!E8))/Assumptions!E7,"--") | D10: =IFERROR(MAX(0,SUMPRODUCT(Assumptions!C28*D5*(1+D9)^{1,2,3,4,5,6,7,8,9,10},1/(1+B10)^({1,2,3,4,5,6,7,8,9,10}-Assumptions!C31))+Assumptions!C28*D5*(1+D9)^10*(1+D6)/MAX(B10-D6,0.01)/(1+B10)^(10-Assumptions!C31)-(Assumptions!C8-Assumptions!E8))/Assumptions!E7,"--") | E10: =IFERROR(MAX(0,SUMPRODUCT(Assumptions!C28*D5*(1+E9)^{1,2,3,4,5,6,7,8,9,10},1/(1+B10)^({1,2,3,4,5,6,7,8,9,10}-Assumptions!C31))+Assumptions!C28*D5*(1+E9)^10*(1+D6)/MAX(B10-D6,0.01)/(1+B10)^(10-Assumptions!C31)-(Assumptions!C8-Assumptions!E8))/Assumptions!E7,"--") | F10: =IFERROR(MAX(0,SUMPRODUCT(Assumptions!C28*D5*(1+F9)^{1,2,3,4,5,6,7,8,9,10},1/(1+B10)^({1,2,3,4,5,6,7,8,9,10}-Assumptions!C31))+Assumptions!C28*D5*(1+F9)^10*(1+D6)/MAX(B10-D6,0.01)/(1+B10)^(10-Assumptions!C31)-(Assumptions!C8-Assumptions!E8))/Assumptions!E7,"--") | G10: =IFERROR(MAX(0,SUMPRODUCT(Assumptions!C28*D5*(1+G9)^{1,2,3,4,5,6,7,8,9,10},1/(1+B10)^({1,2,3,4,5,6,7,8,9,10}-Assumptions!C31))+Assumptions!C28*D5*(1+G9)^10*(1+D6)/MAX(B10-D6,0.01)/(1+B10)^(10-Assumptions!C31)-(Assumptions!C8-Assumptions!E8))/Assumptions!E7,"--") | H10: =IFERROR(MAX(0,SUMPRODUCT(Assumptions!C28*D5*(1+H9)^{1,2,3,4,5,6,7,8,9,10},1/(1+B10)^({1,2,3,4,5,6,7,8,9,10}-Assumptions!C31))+Assumptions!C28*D5*(1+H9)^10*(1+D6)/MAX(B10-D6,0.01)/(1+B10)^(10-Assumptions!C31)-(Assumptions!C8-Assumptions!E8))/Assumptions!E7,"--") | I10: =IFERROR(MAX(0,SUMPRODUCT(Assumptions!C28*D5*(1+I9)^{1,2,3,4,5,6,7,8,9,10},1/(1+B10)^({1,2,3,4,5,6,7,8,9,10}-Assumptions!C31))+Assumptions!C28*D5*(1+I9)^10*(1+D6)/MAX(B10-D6,0.01)/(1+B10)^(10-Assumptions!C31)-(Assumptions!C8-Assumptions!E8))/Assumptions!E7,"--") | J10: =IFERROR(MAX(0,SUMPRODUCT(Assumptions!C28*D5*(1+J9)^{1,2,3,4,5,6,7,8,9,10},1/(1+B10)^({1,2,3,4,5,6,7,8,9,10}-Assumptions!C31))+Assumptions!C28*D5*(1+J9)^10*(1+D6)/MAX(B10-D6,0.01)/(1+B10)^(10-Assumptions!C31)-(Assumptions!C8-Assumptions!E8))/Assumptions!E7,"--") | K10: =IFERROR(MAX(0,SUMPRODUCT(Assumptions!C28*D5*(1+K9)^{1,2,3,4,5,6,7,8,9,10},1/(1+B10)^({1,2,3,4,5,6,7,8,9,10}-Assumptions!C31))+Assumptions!C28*D5*(1+K9)^10*(1+D6)/MAX(B10-D6,0.01)/(1+B10)^(10-Assumptions!C31)-(Assumptions!C8-Assumptions!E8))/Assumptions!E7,"--") | L10: =IFERROR(MAX(0,SUMPRODUCT(Assumptions!C28*D5*(1+L9)^{1,2,3,4,5,6,7,8,9,10},1/(1+B10)^({1,2,3,4,5,6,7,8,9,10}-Assumptions!C31))+Assumptions!C28*D5*(1+L9)^10*(1+D6)/MAX(B10-D6,0.01)/(1+B10)^(10-Assumptions!C31)-(Assumptions!C8-Assumptions!E8))/Assumptions!E7,"--")
